Workbook

Sheet INDICE
A1: DEPARTAMENTO ADMINISTRATIVO DE PLANEACIÓN
A2: DIRECCIÓN DE INFORMACIÓN DEPARTAMENTAL
A3: DEPARTAMENTO DE ANTIOQUIA DESAGREGACIÓN DEL PRODUCTO INTERNO BRUTO -PIB- POR MUNICIPIO 2015 - 2022 preliminar
A5: Tabla N° | B5: Descripción
A6: Tabla 1 | B6: Valor Agregado por grandes ramas de actividad, sector Económico y PIB para los 125 municipios de Antioquia anual Cifras a precios corrientes , Miles de millones de pesos
A7: Tabla 2 | B7: Valor Agregado por grandes ramas de actividad, sector Económico y PIB para los 125 municipios de Antioquia anual Cifras a precios constantes, Series encadenadas de volumen con año de referencia 2015 Miles de millones de pesos
A8: Tabla 3 | B8: Valor Agregado por grandes ramas de actividad, sector Económico y PIB para los 9 subregiones de Antioquia anual Cifras a precios corrientes , Miles de millones de pesos
A9: Tabla 4 | B9: Participación porcentual del Valor Agregado por grandes ramas de actividad, sector Económico y PIB para los 9 subregiones de Antioquia en el total Departamental anual
A10: Tabla 5 | B10: Distribución porcentual de las actividades y ramas de económicas en el valor Agregado, en las 9 subregiones de Antioquia anual
A11: Tabla 6 | B11: Coeficiente de especialización regional por actividades y ramas de económicas, en las 9 subregiones de Antioquia anual
A12: Tabla 7 | B12: Producto Interno Bruto a precios corrientes municipal, subregional y Departamental (miles de Millones de pesos) 2015 - 2022pr
A13: Tabla 8 | B13: Participación % municipal en la subregión y Departamento 2015 - 2022pr
A14: Tabla 9 | B14: Producto Interno Bruto municipal, Subregional y Departamental en precios constantes, Series encadenadas de volumen con año de referencia 2015, Años 2015 - 2022pr (miles de Millones de pesos)
A15: Tabla 10 | B15: Tasa de variación del Producto Interno Bruto a precios constantes municipal, Subregional y Departamental, Series encadenadas de volumen con año de referencia 2015, 2016 - 2022pr
A16: Tabla 11 | B16: Valor Agregado municipal en precios corrientes por sectores 2015 - 2022pr
... A27: Tabla 22 | B27: POBLACIÓN TOTAL POR MUNICIPIOS DEPARTAMENTO DE ANTIOQUIA 1985 -2035 (Fuente: Retroproyecciones y proyecciones DANE publicadas 22/03/2023)
A29: NOTAS (Versión 22/12/2023)
A30: a) Valores estimados por la Escuela de Finanzas Económica y Gobierno de la Universidad de EAFIT en cumplimiento del Contrato N° 4600014337 para la “Actualización de la metodología para la estimación de la participación en el Producto Interno Bruto para los 125 municipios del Departamento de Antioquia y su cálculo para los años 2015 al 2020".
A31: b) Valores de los años 2021 y 2022 estimados por la Dirección de Información Departamental desarrollando la actualización metodológica realizada por la universidad EAFIL dentro del contrato N° 4600014337 para la “Actualización de la metodología para la estimación de la participación en el Producto Interno Bruto para los 125 municipios del Departamento de Antioquia y su cálculo para los años 2015 al 2020".
A32: c) Valores estimados a partir de la publicación de las Cuentas Nacionales Anuales, PIB Departamental del 30 de mayo de 2023.
A33: d) Los valores del año 2020 2021 se encuentran estado provisional (p) , 2022 se encuentra en estado preliminar (pr); de acuerdo a la publicación citada anteriormente.
A34: e) En la rama de actividad C. Industrias manufactureras, M+N Actividades profesionales, científicas y técnicas; Actividades de servicios administrativos y de apoyo su usan, A. Agricultura se usan las Matrices de oferta y utilización la última versión disponible publicada por el DANE en el Sistema de Cuentas Nacionales corresponde a la vigencia 2021 provisional.
A35: f) La metodología incluye la homologación con la publicación del DANE de Valor agregado por municipio: serie 2011-2021 provisional, para estimar los valores del 2022 se usa como base los valores 2021 y los valores Departamentales 30 de mayo de 2023.
A36: g) En la rama de actividad C. Industrias manufactureras, se usa información de la Encuesta Anual Manufacturera al momento de su estimación el DANE no ha publicado los valores 2022, se usan los valores disponibles 2021.

Sheet PIB-MPAL CORRRIENTES ANUAL
A1: Tabla 1 | W1: AÑO:
A2: ="Valor Agregado por grandes ramas de actividad, sector Económico y PIB para los 125 municipios de Antioquia año: "&W2&IF(OR(W2=2021,W2=2020)," provisional ",IF(W2=2022," preliminar ",""))&" Cifras a precios corrientes , Miles de millones de pesos" -> Valor Agregado por grandes ramas de actividad, sector Económico y PIB para los 125 municipios de Antioquia año: 2019 Cifras a precios corrientes , Miles de millones de pesos | W2: 2019
A4: Código DANE del municipio | B4: Subregiones | C4: Esquema Asociativo Territorial | D4: Municipios y distritos | E4: Agricultura, ganadería, caza, silvicultura y pesca | F4: Explotación de minas y canteras | G4: Industrias manufactureras | H4: Construcción | I4: Suministro de electricidad, gas, vapor y aire acondicionado; distribución de agua; evacuación y tratamiento de aguas residuales, gestión de desechos y actividades de saneamiento ambiental | J4: Comercio al por mayor y al por menor; reparación de vehículos automotores y motocicletas; transporte y almacenamiento; alojamiento y servicios de comida | K4: Información y comunicaciones | L4: Actividades financieras y de seguros | M4: Actividades inmobiliarias | N4: Actividades profesionales, científicas y técnicas; actividades de servicios administrativos y de apoyo | O4: Administración pública y defensa; planes de seguridad social de afiliación obligatoria; educación; actividades de atención de la salud humana y de servicios sociales | P4: Actividades artísticas, de entretenimiento y recreación y otras actividades de servicios; actividades de los hogares individuales en calidad de empleadores; actividades no diferenciadas de los hogares individuales como productores de bienes y servicios para uso propio | Q4: Actividades Primarias | R4: Actividades Secundarias | S4: Actividades Terciarias | T4: Valor Agregado | U4: Derechos e impuestos | V4: Producto Interno Bruto PIB | W4: Participación porcentual del Producto Interno Bruto PIB en el Departamento | X4: Población | Y4: Valor Agregado Per cápita (Miles de pesos) | Z4: Producto Interno Bruto PIB Per cápita (Miles de pesos) | AA4: Logaritmo base 10 del Valor Agregado Per cápita (Miles de pesos) | AB4: Logaritmo base 10 del Producto Interno Bruto PIB Per cápita (Miles de pesos) | AE4: Nota: las actividades comprenden la siguiente desagregación:
D5: Total departamento | E5: =E6+E17+E24+E31+E42+E60+E80+E104+E128 -> 8918.4641 | F5: =F6+F17+F24+F31+F42+F60+F80+F104+F128 -> 3175.2932 | G5: =G6+G17+G24+G31+G42+G60+G80+G104+G128 -> 22127.443 | H5: =H6+H17+H24+H31+H42+H60+H80+H104+H128 -> 11048.784 | I5: =I6+I17+I24+I31+I42+I60+I80+I104+I128 -> 7053.7836 | J5: =J6+J17+J24+J31+J42+J60+J80+J104+J128 -> 26342.511 | K5: =K6+K17+K24+K31+K42+K60+K80+K104+K128 -> 4286.9799 | L5: =L6+L17+L24+L31+L42+L60+L80+L104+L128 -> 7515.704 | ... V5: =V6+V17+V24+V31+V42+V60+V80+V104+V128 -> 153559.45 | W5: =V5/$V$5 -> 1 | X5: =X6+X17+X24+X31+X42+X60+X80+X104+X128 -> 6550206 | Y5: =(T5/X5)*1000000 -> 21291.73 | Z5: =(V5/X5)*1000000 -> 23443.453 | AA5: =LOG(Y5) -> 4.3282109 | AB5: =LOG(Z5) -> 4.3700216 | AE5: Primarias *
A6: SR01 | B6: Total Valle de Aburrá | E6: =SUM(E7:E16) -> 452.01105 | F6: =SUM(F7:F16) -> 53.569416 | G6: =SUM(G7:G16) -> 17463.33 | H6: =SUM(H7:H16) -> 7822.5484 | I6: =SUM(I7:I16) -> 3891.6287 | J6: =SUM(J7:J16) -> 19502.665 | K6: =SUM(K7:K16) -> 3163.5246 | L6: =SUM(L7:L16) -> 6677.4649 | ... V6: =SUM(V7:V16) -> 103882.83 | W6: =V6/$V$5 -> 0.67649909 | X6: =SUM(X7:X16) -> 3969222 | Y6: =(T6/X6)*1000000 -> 23769.921 | Z6: =(V6/X6)*1000000 -> 26172.088 | AA6: =LOG(Y6) -> 4.3760277 | AB6: =LOG(Z6) -> 4.4178384 | AE6: Agricultura, ganadería, silvicultura y pesca
A7: 05001 | B7: Valle de Aburrá | C7: Área Metropolitana del Valle de Aburrá | D7: Distrito Especial de Ciencia, Tecnología e Innovación de Medellín | E7: =SUMIFS('PIB-Mpal 2015-2022 Corrient '!H$5:H$1012,'PIB-Mpal 2015-2022 Corrient '!$A$5:$A$1012,$W$2,'PIB-Mpal 2015-2022 Corrient '!$E$5:$E$1012,$A7) -> 156.61362 | F7: =SUMIFS('PIB-Mpal 2015-2022 Corrient '!I$5:I$1012,'PIB-Mpal 2015-2022 Corrient '!$A$5:$A$1012,$W$2,'PIB-Mpal 2015-2022 Corrient '!$E$5:$E$1012,$A7) -> 2.2789548 | G7: =SUMIFS('PIB-Mpal 2015-2022 Corrient '!K$5:K$1012,'PIB-Mpal 2015-2022 Corrient '!$A$5:$A$1012,$W$2,'PIB-Mpal 2015-2022 Corrient '!$E$5:$E$1012,$A7) -> 7876.9209 | H7: =SUMIFS('PIB-Mpal 2015-2022 Corrient '!L$5:L$1012,'PIB-Mpal 2015-2022 Corrient '!$A$5:$A$1012,$W$2,'PIB-Mpal 2015-2022 Corrient '!$E$5:$E$1012,$A7) -> 5138.9618 | I7: =SUMIFS('PIB-Mpal 2015-2022 Corrient '!N$5:N$1012,'PIB-Mpal 2015-2022 Corrient '!$A$5:$A$1012,$W$2,'PIB-Mpal 2015-2022 Corrient '!$E$5:$E$1012,$A7) -> 2380.4576 | J7: =SUMIFS('PIB-Mpal 2015-2022 Corrient '!O$5:O$1012,'PIB-Mpal 2015-2022 Corrient '!$A$5:$A$1012,$W$2,'PIB-Mpal 2015-2022 Corrient '!$E$5:$E$1012,$A7) -> 12722.867 | K7: =SUMIFS('PIB-Mpal 2015-2022 Corrient '!P$5:P$1012,'PIB-Mpal 2015-2022 Corrient '!$A$5:$A$1012,$W$2,'PIB-Mpal 2015-2022 Corrient '!$E$5:$E$1012,$A7) -> 1962.1236 | L7: =SUMIFS('PIB-Mpal 2015-2022 Corrient '!Q$5:Q$1012,'PIB-Mpal 2015-2022 Corrient '!$A$5:$A$1012,$W$2,'PIB-Mpal 2015-2022 Corrient '!$E$5:$E$1012,$A7) -> 5558.0039 | M7: =SUMIFS('PIB-Mpal 2015-2022 Corrient '!R$5:R$1012,'PIB-Mpal 2015-2022 Corrient '!$A$5:$A$1012,$W$2,'PIB-Mpal 2015-2022 Corrient '!$E$5:$E$1012,$A7) -> 6770.7309 | N7: =SUMIFS('PIB-Mpal 2015-2022 Corrient '!S$5:S$1012,'PIB-Mpal 2015-2022 Corrient '!$A$5:$A$1012,$W$2,'PIB-Mpal 2015-2022 Corrient '!$E$5:$E$1012,$A7) -> 6471.2999 | O7: =SUMIFS('PIB-Mpal 2015-2022 Corrient '!T$5:T$1012,'PIB-Mpal 2015-2022 Corrient '!$A$5:$A$1012,$W$2,'PIB-Mpal 2015-2022 Corrient '!$E$5:$E$1012,$A7) -> 8627.5188 | P7: =SUMIFS('PIB-Mpal 2015-2022 Corrient '!U$5:U$1012,'PIB-Mpal 2015-2022 Corrient '!$A$5:$A$1012,$W$2,'PIB-Mpal 2015-2022 Corrient '!$E$5:$E$1012,$A7) -> 1767.1888 | Q7: =SUMIFS('PIB-Mpal 2015-2022 Corrient '!J$5:J$1012,'PIB-Mpal 2015-2022 Corrient '!$A$5:$A$1012,$W$2,'PIB-Mpal 2015-2022 Corrient '!$E$5:$E$1012,$A7) -> 158.89257 | R7: =SUMIFS('PIB-Mpal 2015-2022 Corrient '!M$5:M$1012,'PIB-Mpal 2015-2022 Corrient '!$A$5:$A$1012,$W$2,'PIB-Mpal 2015-2022 Corrient '!$E$5:$E$1012,$A7) -> 13015.883 | S7: =SUMIFS('PIB-Mpal 2015-2022 Corrient '!V$5:V$1012,'PIB-Mpal 2015-2022 Corrient '!$A$5:$A$1012,$W$2,'PIB-Mpal 2015-2022 Corrient '!$E$5:$E$1012,$A7) -> 46260.191 | T7: =SUMIFS('PIB-Mpal 2015-2022 Corrient '!W$5:W$1012,'PIB-Mpal 2015-2022 Corrient '!$A$5:$A$1012,$W$2,'PIB-Mpal 2015-2022 Corrient '!$E$5:$E$1012,$A7) -> 59434.966 | U7: =SUMIFS('PIB-Mpal 2015-2022 Corrient '!X$5:X$1012,'PIB-Mpal 2015-2022 Corrient '!$A$5:$A$1012,$W$2,'PIB-Mpal 2015-2022 Corrient '!$E$5:$E$1012,$A7) -> 6006.4453 | V7: =SUMIFS('PIB-Mpal 2015-2022 Corrient '!Y$5:Y$1012,'PIB-Mpal 2015-2022 Corrient '!$A$5:$A$1012,$W$2,'PIB-Mpal 2015-2022 Corrient '!$E$5:$E$1012,$A7) -> 65441.412 | W7: =V7/$V$5 -> 0.42616337 | X7: =INDEX(POBLACION!$C$4:$W$128,MATCH(A7,POBLACION!$A$4:$A$128,0),MATCH($W$2,POBLACION!$C$3:$W$3,0)) -> 2483545 | Y7: =(T7/X7)*1000000 -> 23931.504 | Z7: =(V7/X7)*1000000 -> 26350 | AA7: =LOG(Y7) -> 4.37897 | AB7: =LOG(Z7) -> 4.4207806 | AE7: Explotación de minas y canteras
A8: 05079 | B8: Valle de Aburrá | C8: Área Metropolitana del Valle de Aburrá | D8: Barbosa | E8: =SUMIFS('PIB-Mpal 2015-2022 Corrient '!H$5:H$1012,'PIB-Mpal 2015-2022 Corrient '!$A$5:$A$1012,$W$2,'PIB-Mpal 2015-2022 Corrient '!$E$5:$E$1012,$A8) -> 94.782432 | F8: =SUMIFS('PIB-Mpal 2015-2022 Corrient '!I$5:I$1012,'PIB-Mpal 2015-2022 Corrient '!$A$5:$A$1012,$W$2,'PIB-Mpal 2015-2022 Corrient '!$E$5:$E$1012,$A8) -> 3.3560323 | G8: =SUMIFS('PIB-Mpal 2015-2022 Corrient '!K$5:K$1012,'PIB-Mpal 2015-2022 Corrient '!$A$5:$A$1012,$W$2,'PIB-Mpal 2015-2022 Corrient '!$E$5:$E$1012,$A8) -> 368.83379 | H8: =SUMIFS('PIB-Mpal 2015-2022 Corrient '!L$5:L$1012,'PIB-Mpal 2015-2022 Corrient '!$A$5:$A$1012,$W$2,'PIB-Mpal 2015-2022 Corrient '!$E$5:$E$1012,$A8) -> 93.970492 | I8: =SUMIFS('PIB-Mpal 2015-2022 Corrient '!N$5:N$1012,'PIB-Mpal 2015-2022 Corrient '!$A$5:$A$1012,$W$2,'PIB-Mpal 2015-2022 Corrient '!$E$5:$E$1012,$A8) -> 140.46509 | J8: =SUMIFS('PIB-Mpal 2015-2022 Corrient '!O$5:O$1012,'PIB-Mpal 2015-2022 Corrient '!$A$5:$A$1012,$W$2,'PIB-Mpal 2015-2022 Corrient '!$E$5:$E$1012,$A8) -> 101.78784 | K8: =SUMIFS('PIB-Mpal 2015-2022 Corrient '!P$5:P$1012,'PIB-Mpal 2015-2022 Corrient '!$A$5:$A$1012,$W$2,'PIB-Mpal 2015-2022 Corrient '!$E$5:$E$1012,$A8) -> 16.388756 | L8: =SUMIFS('PIB-Mpal 2015-2022 Corrient '!Q$5:Q$1012,'PIB-Mpal 2015-2022 Corrient '!$A$5:$A$1012,$W$2,'PIB-Mpal 2015-2022 Corrient '!$E$5:$E$1012,$A8) -> 10.183371 | M8: =SUMIFS('PIB-Mpal 2015-2022 Corrient '!R$5:R$1012,'PIB-Mpal 2015-2022 Corrient '!$A$5:$A$1012,$W$2,'PIB-Mpal 2015-2022 Corrient '!$E$5:$E$1012,$A8) -> 56.385601 | N8: =SUMIFS('PIB-Mpal 2015-2022 Corrient '!S$5:S$1012,'PIB-Mpal 2015-2022 Corrient '!$A$5:$A$1012,$W$2,'PIB-Mpal 2015-2022 Corrient '!$E$5:$E$1012,$A8) -> 63.177791 | O8: =SUMIFS('PIB-Mpal 2015-2022 Corrient '!T$5:T$1012,'PIB-Mpal 2015-2022 Corrient '!$A$5:$A$1012,$W$2,'PIB-Mpal 2015-2022 Corrient '!$E$5:$E$1012,$A8) -> 58.464028 | P8: =SUMIFS('PIB-Mpal 2015-2022 Corrient '!U$5:U$1012,'PIB-Mpal 2015-2022 Corrient '!$A$5:$A$1012,$W$2,'PIB-Mpal 2015-2022 Corrient '!$E$5:$E$1012,$A8) -> 20.200567 | Q8: =SUMIFS('PIB-Mpal 2015-2022 Corrient '!J$5:J$1012,'PIB-Mpal 2015-2022 Corrient '!$A$5:$A$1012,$W$2,'PIB-Mpal 2015-2022 Corrient '!$E$5:$E$1012,$A8) -> 98.138464 | R8: =SUMIFS('PIB-Mpal 2015-2022 Corrient '!M$5:M$1012,'PIB-Mpal 2015-2022 Corrient '!$A$5:$A$1012,$W$2,'PIB-Mpal 2015-2022 Corrient '!$E$5:$E$1012,$A8) -> 462.80428 | S8: =SUMIFS('PIB-Mpal 2015-2022 Corrient '!V$5:V$1012,'PIB-Mpal 2015-2022 Corrient '!$A$5:$A$1012,$W$2,'PIB-Mpal 2015-2022 Corrient '!$E$5:$E$1012,$A8) -> 467.05305 | T8: =SUMIFS('PIB-Mpal 2015-2022 Corrient '!W$5:W$1012,'PIB-Mpal 2015-2022 Corrient '!$A$5:$A$1012,$W$2,'PIB-Mpal 2015-2022 Corrient '!$E$5:$E$1012,$A8) -> 1027.9958 | U8: =SUMIFS('PIB-Mpal 2015-2022 Corrient '!X$5:X$1012,'PIB-Mpal 2015-2022 Corrient '!$A$5:$A$1012,$W$2,'PIB-Mpal 2015-2022 Corrient '!$E$5:$E$1012,$A8) -> 103.88835 | V8: =SUMIFS('PIB-Mpal 2015-2022 Corrient '!Y$5:Y$1012,'PIB-Mpal 2015-2022 Corrient '!$A$5:$A$1012,$W$2,'PIB-Mpal 2015-2022 Corrient '!$E$5:$E$1012,$A8) -> 1131.8841 | W8: =V8/$V$5 -> 0.0073709834 | X8: =INDEX(POBLACION!$C$4:$W$128,MATCH(A8,POBLACION!$A$4:$A$128,0),MATCH($W$2,POBLACION!$C$3:$W$3,0)) -> 53242 | Y8: =(T8/X8)*1000000 -> 19307.986 | Z8: =(V8/X8)*1000000 -> 21259.234 | AA8: =LOG(Y8) -> 4.285737 | AB8: =LOG(Z8) -> 4.3275476 | AE8: Secundarias **
A9: 05088 | B9: Valle de Aburrá | C9: Área Metropolitana del Valle de Aburrá | D9: Bello | E9: =SUMIFS('PIB-Mpal 2015-2022 Corrient '!H$5:H$1012,'PIB-Mpal 2015-2022 Corrient '!$A$5:$A$1012,$W$2,'PIB-Mpal 2015-2022 Corrient '!$E$5:$E$1012,$A9) -> 32.765664 | F9: =SUMIFS('PIB-Mpal 2015-2022 Corrient '!I$5:I$1012,'PIB-Mpal 2015-2022 Corrient '!$A$5:$A$1012,$W$2,'PIB-Mpal 2015-2022 Corrient '!$E$5:$E$1012,$A9) -> 1.0753017 | G9: =SUMIFS('PIB-Mpal 2015-2022 Corrient '!K$5:K$1012,'PIB-Mpal 2015-2022 Corrient '!$A$5:$A$1012,$W$2,'PIB-Mpal 2015-2022 Corrient '!$E$5:$E$1012,$A9) -> 680.90774 | H9: =SUMIFS('PIB-Mpal 2015-2022 Corrient '!L$5:L$1012,'PIB-Mpal 2015-2022 Corrient '!$A$5:$A$1012,$W$2,'PIB-Mpal 2015-2022 Corrient '!$E$5:$E$1012,$A9) -> 528.90776 | I9: =SUMIFS('PIB-Mpal 2015-2022 Corrient '!N$5:N$1012,'PIB-Mpal 2015-2022 Corrient '!$A$5:$A$1012,$W$2,'PIB-Mpal 2015-2022 Corrient '!$E$5:$E$1012,$A9) -> 275.13427 | J9: =SUMIFS('PIB-Mpal 2015-2022 Corrient '!O$5:O$1012,'PIB-Mpal 2015-2022 Corrient '!$A$5:$A$1012,$W$2,'PIB-Mpal 2015-2022 Corrient '!$E$5:$E$1012,$A9) -> 1651.8669 | K9: =SUMIFS('PIB-Mpal 2015-2022 Corrient '!P$5:P$1012,'PIB-Mpal 2015-2022 Corrient '!$A$5:$A$1012,$W$2,'PIB-Mpal 2015-2022 Corrient '!$E$5:$E$1012,$A9) -> 304.79771 | L9: =SUMIFS('PIB-Mpal 2015-2022 Corrient '!Q$5:Q$1012,'PIB-Mpal 2015-2022 Corrient '!$A$5:$A$1012,$W$2,'PIB-Mpal 2015-2022 Corrient '!$E$5:$E$1012,$A9) -> 212.3682 | M9: =SUMIFS('PIB-Mpal 2015-2022 Corrient '!R$5:R$1012,'PIB-Mpal 2015-2022 Corrient '!$A$5:$A$1012,$W$2,'PIB-Mpal 2015-2022 Corrient '!$E$5:$E$1012,$A9) -> 752.29485 | N9: =SUMIFS('PIB-Mpal 2015-2022 Corrient '!S$5:S$1012,'PIB-Mpal 2015-2022 Corrient '!$A$5:$A$1012,$W$2,'PIB-Mpal 2015-2022 Corrient '!$E$5:$E$1012,$A9) -> 645.00039 | O9: =SUMIFS('PIB-Mpal 2015-2022 Corrient '!T$5:T$1012,'PIB-Mpal 2015-2022 Corrient '!$A$5:$A$1012,$W$2,'PIB-Mpal 2015-2022 Corrient '!$E$5:$E$1012,$A9) -> 833.96157 | P9: =SUMIFS('PIB-Mpal 2015-2022 Corrient '!U$5:U$1012,'PIB-Mpal 2015-2022 Corrient '!$A$5:$A$1012,$W$2,'PIB-Mpal 2015-2022 Corrient '!$E$5:$E$1012,$A9) -> 292.89696 | Q9: =SUMIFS('PIB-Mpal 2015-2022 Corrient '!J$5:J$1012,'PIB-Mpal 2015-2022 Corrient '!$A$5:$A$1012,$W$2,'PIB-Mpal 2015-2022 Corrient '!$E$5:$E$1012,$A9) -> 33.840966 | R9: =SUMIFS('PIB-Mpal 2015-2022 Corrient '!M$5:M$1012,'PIB-Mpal 2015-2022 Corrient '!$A$5:$A$1012,$W$2,'PIB-Mpal 2015-2022 Corrient '!$E$5:$E$1012,$A9) -> 1209.8155 | S9: =SUMIFS('PIB-Mpal 2015-2022 Corrient '!V$5:V$1012,'PIB-Mpal 2015-2022 Corrient '!$A$5:$A$1012,$W$2,'PIB-Mpal 2015-2022 Corrient '!$E$5:$E$1012,$A9) -> 4968.3208 | T9: =SUMIFS('PIB-Mpal 2015-2022 Corrient '!W$5:W$1012,'PIB-Mpal 2015-2022 Corrient '!$A$5:$A$1012,$W$2,'PIB-Mpal 2015-2022 Corrient '!$E$5:$E$1012,$A9) -> 6211.9773 | U9: =SUMIFS('PIB-Mpal 2015-2022 Corrient '!X$5:X$1012,'PIB-Mpal 2015-2022 Corrient '!$A$5:$A$1012,$W$2,'PIB-Mpal 2015-2022 Corrient '!$E$5:$E$1012,$A9) -> 627.77695 | V9: =SUMIFS('PIB-Mpal 2015-2022 Corrient '!Y$5:Y$1012,'PIB-Mpal 2015-2022 Corrient '!$A$5:$A$1012,$W$2,'PIB-Mpal 2015-2022 Corrient '!$E$5:$E$1012,$A9) -> 6839.7542 | W9: =V9/$V$5 -> 0.044541409 | X9: =INDEX(POBLACION!$C$4:$W$128,MATCH(A9,POBLACION!$A$4:$A$128,0),MATCH($W$2,POBLACION!$C$3:$W$3,0)) -> 538527 | Y9: =(T9/X9)*1000000 -> 11535.127 | Z9: =(V9/X9)*1000000 -> 12700.857 | AA9: =LOG(Y9) -> 4.0620224 | AB9: =LOG(Z9) -> 4.103833 | AE9: Industrias manufactureras
A10: 05129 | B10: Valle de Aburrá | C10: Área Metropolitana del Valle de Aburrá | D10: Caldas | E10: =SUMIFS('PIB-Mpal 2015-2022 Corrient '!H$5:H$1012,'PIB-Mpal 2015-2022 Corrient '!$A$5:$A$1012,$W$2,'PIB-Mpal 2015-2022 Corrient '!$E$5:$E$1012,$A10) -> 65.221423 | F10: =SUMIFS('PIB-Mpal 2015-2022 Corrient '!I$5:I$1012,'PIB-Mpal 2015-2022 Corrient '!$A$5:$A$1012,$W$2,'PIB-Mpal 2015-2022 Corrient '!$E$5:$E$1012,$A10) -> 0 | G10: =SUMIFS('PIB-Mpal 2015-2022 Corrient '!K$5:K$1012,'PIB-Mpal 2015-2022 Corrient '!$A$5:$A$1012,$W$2,'PIB-Mpal 2015-2022 Corrient '!$E$5:$E$1012,$A10) -> 262.55303 | H10: =SUMIFS('PIB-Mpal 2015-2022 Corrient '!L$5:L$1012,'PIB-Mpal 2015-2022 Corrient '!$A$5:$A$1012,$W$2,'PIB-Mpal 2015-2022 Corrient '!$E$5:$E$1012,$A10) -> 76.471003 | I10: =SUMIFS('PIB-Mpal 2015-2022 Corrient '!N$5:N$1012,'PIB-Mpal 2015-2022 Corrient '!$A$5:$A$1012,$W$2,'PIB-Mpal 2015-2022 Corrient '!$E$5:$E$1012,$A10) -> 40.617619 | J10: =SUMIFS('PIB-Mpal 2015-2022 Corrient '!O$5:O$1012,'PIB-Mpal 2015-2022 Corrient '!$A$5:$A$1012,$W$2,'PIB-Mpal 2015-2022 Corrient '!$E$5:$E$1012,$A10) -> 244.29052 | K10: =SUMIFS('PIB-Mpal 2015-2022 Corrient '!P$5:P$1012,'PIB-Mpal 2015-2022 Corrient '!$A$5:$A$1012,$W$2,'PIB-Mpal 2015-2022 Corrient '!$E$5:$E$1012,$A10) -> 48.97591 | L10: =SUMIFS('PIB-Mpal 2015-2022 Corrient '!Q$5:Q$1012,'PIB-Mpal 2015-2022 Corrient '!$A$5:$A$1012,$W$2,'PIB-Mpal 2015-2022 Corrient '!$E$5:$E$1012,$A10) -> 37.279052 | M10: =SUMIFS('PIB-Mpal 2015-2022 Corrient '!R$5:R$1012,'PIB-Mpal 2015-2022 Corrient '!$A$5:$A$1012,$W$2,'PIB-Mpal 2015-2022 Corrient '!$E$5:$E$1012,$A10) -> 127.80909 | N10: =SUMIFS('PIB-Mpal 2015-2022 Corrient '!S$5:S$1012,'PIB-Mpal 2015-2022 Corrient '!$A$5:$A$1012,$W$2,'PIB-Mpal 2015-2022 Corrient '!$E$5:$E$1012,$A10) -> 108.36785 | O10: =SUMIFS('PIB-Mpal 2015-2022 Corrient '!T$5:T$1012,'PIB-Mpal 2015-2022 Corrient '!$A$5:$A$1012,$W$2,'PIB-Mpal 2015-2022 Corrient '!$E$5:$E$1012,$A10) -> 137.43932 | P10: =SUMIFS('PIB-Mpal 2015-2022 Corrient '!U$5:U$1012,'PIB-Mpal 2015-2022 Corrient '!$A$5:$A$1012,$W$2,'PIB-Mpal 2015-2022 Corrient '!$E$5:$E$1012,$A10) -> 34.913718 | Q10: =SUMIFS('PIB-Mpal 2015-2022 Corrient '!J$5:J$1012,'PIB-Mpal 2015-2022 Corrient '!$A$5:$A$1012,$W$2,'PIB-Mpal 2015-2022 Corrient '!$E$5:$E$1012,$A10) -> 65.221423 | R10: =SUMIFS('PIB-Mpal 2015-2022 Corrient '!M$5:M$1012,'PIB-Mpal 2015-2022 Corrient '!$A$5:$A$1012,$W$2,'PIB-Mpal 2015-2022 Corrient '!$E$5:$E$1012,$A10) -> 339.02403 | S10: =SUMIFS('PIB-Mpal 2015-2022 Corrient '!V$5:V$1012,'PIB-Mpal 2015-2022 Corrient '!$A$5:$A$1012,$W$2,'PIB-Mpal 2015-2022 Corrient '!$E$5:$E$1012,$A10) -> 779.69307 | T10: =SUMIFS('PIB-Mpal 2015-2022 Corrient '!W$5:W$1012,'PIB-Mpal 2015-2022 Corrient '!$A$5:$A$1012,$W$2,'PIB-Mpal 2015-2022 Corrient '!$E$5:$E$1012,$A10) -> 1183.9385 | U10: =SUMIFS('PIB-Mpal 2015-2022 Corrient '!X$5:X$1012,'PIB-Mpal 2015-2022 Corrient '!$A$5:$A$1012,$W$2,'PIB-Mpal 2015-2022 Corrient '!$E$5:$E$1012,$A10) -> 119.64778 | V10: =SUMIFS('PIB-Mpal 2015-2022 Corrient '!Y$5:Y$1012,'PIB-Mpal 2015-2022 Corrient '!$A$5:$A$1012,$W$2,'PIB-Mpal 2015-2022 Corrient '!$E$5:$E$1012,$A10) -> 1303.5863 | W10: =V10/$V$5 -> 0.0084891312 | X10: =INDEX(POBLACION!$C$4:$W$128,MATCH(A10,POBLACION!$A$4:$A$128,0),MATCH($W$2,POBLACION!$C$3:$W$3,0)) -> 81658 | Y10: =(T10/X10)*1000000 -> 14498.745 | Z10: =(V10/X10)*1000000 -> 15963.975 | AA10: =LOG(Y10) -> 4.1613304 | AB10: =LOG(Z10) -> 4.2031411 | AE10: Construcción
A11: 05212 | B11: Valle de Aburrá | C11: Área Metropolitana del Valle de Aburrá | D11: Copacabana | E11: =SUMIFS('PIB-Mpal 2015-2022 Corrient '!H$5:H$1012,'PIB-Mpal 2015-2022 Corrient '!$A$5:$A$1012,$W$2,'PIB-Mpal 2015-2022 Corrient '!$E$5:$E$1012,$A11) -> 10.114864 | F11: =SUMIFS('PIB-Mpal 2015-2022 Corrient '!I$5:I$1012,'PIB-Mpal 2015-2022 Corrient '!$A$5:$A$1012,$W$2,'PIB-Mpal 2015-2022 Corrient '!$E$5:$E$1012,$A11) -> 0.12092898 | G11: =SUMIFS('PIB-Mpal 2015-2022 Corrient '!K$5:K$1012,'PIB-Mpal 2015-2022 Corrient '!$A$5:$A$1012,$W$2,'PIB-Mpal 2015-2022 Corrient '!$E$5:$E$1012,$A11) -> 412.11604 | H11: =SUMIFS('PIB-Mpal 2015-2022 Corrient '!L$5:L$1012,'PIB-Mpal 2015-2022 Corrient '!$A$5:$A$1012,$W$2,'PIB-Mpal 2015-2022 Corrient '!$E$5:$E$1012,$A11) -> 165.3795 | I11: =SUMIFS('PIB-Mpal 2015-2022 Corrient '!N$5:N$1012,'PIB-Mpal 2015-2022 Corrient '!$A$5:$A$1012,$W$2,'PIB-Mpal 2015-2022 Corrient '!$E$5:$E$1012,$A11) -> 52.146456 | J11: =SUMIFS('PIB-Mpal 2015-2022 Corrient '!O$5:O$1012,'PIB-Mpal 2015-2022 Corrient '!$A$5:$A$1012,$W$2,'PIB-Mpal 2015-2022 Corrient '!$E$5:$E$1012,$A11) -> 249.9913 | K11: =SUMIFS('PIB-Mpal 2015-2022 Corrient '!P$5:P$1012,'PIB-Mpal 2015-2022 Corrient '!$A$5:$A$1012,$W$2,'PIB-Mpal 2015-2022 Corrient '!$E$5:$E$1012,$A11) -> 52.499781 | L11: =SUMIFS('PIB-Mpal 2015-2022 Corrient '!Q$5:Q$1012,'PIB-Mpal 2015-2022 Corrient '!$A$5:$A$1012,$W$2,'PIB-Mpal 2015-2022 Corrient '!$E$5:$E$1012,$A11) -> 30.45911 | M11: =SUMIFS('PIB-Mpal 2015-2022 Corrient '!R$5:R$1012,'PIB-Mpal 2015-2022 Corrient '!$A$5:$A$1012,$W$2,'PIB-Mpal 2015-2022 Corrient '!$E$5:$E$1012,$A11) -> 150.60507 | N11: =SUMIFS('PIB-Mpal 2015-2022 Corrient '!S$5:S$1012,'PIB-Mpal 2015-2022 Corrient '!$A$5:$A$1012,$W$2,'PIB-Mpal 2015-2022 Corrient '!$E$5:$E$1012,$A11) -> 114.80496 | O11: =SUMIFS('PIB-Mpal 2015-2022 Corrient '!T$5:T$1012,'PIB-Mpal 2015-2022 Corrient '!$A$5:$A$1012,$W$2,'PIB-Mpal 2015-2022 Corrient '!$E$5:$E$1012,$A11) -> 101.13064 | P11: =SUMIFS('PIB-Mpal 2015-2022 Corrient '!U$5:U$1012,'PIB-Mpal 2015-2022 Corrient '!$A$5:$A$1012,$W$2,'PIB-Mpal 2015-2022 Corrient '!$E$5:$E$1012,$A11) -> 40.654312 | Q11: =SUMIFS('PIB-Mpal 2015-2022 Corrient '!J$5:J$1012,'PIB-Mpal 2015-2022 Corrient '!$A$5:$A$1012,$W$2,'PIB-Mpal 2015-2022 Corrient '!$E$5:$E$1012,$A11) -> 10.235793 | R11: =SUMIFS('PIB-Mpal 2015-2022 Corrient '!M$5:M$1012,'PIB-Mpal 2015-2022 Corrient '!$A$5:$A$1012,$W$2,'PIB-Mpal 2015-2022 Corrient '!$E$5:$E$1012,$A11) -> 577.49554 | S11: =SUMIFS('PIB-Mpal 2015-2022 Corrient '!V$5:V$1012,'PIB-Mpal 2015-2022 Corrient '!$A$5:$A$1012,$W$2,'PIB-Mpal 2015-2022 Corrient '!$E$5:$E$1012,$A11) -> 792.29164 | T11: =SUMIFS('PIB-Mpal 2015-2022 Corrient '!W$5:W$1012,'PIB-Mpal 2015-2022 Corrient '!$A$5:$A$1012,$W$2,'PIB-Mpal 2015-2022 Corrient '!$E$5:$E$1012,$A11) -> 1380.023 | U11: =SUMIFS('PIB-Mpal 2015-2022 Corrient '!X$5:X$1012,'PIB-Mpal 2015-2022 Corrient '!$A$5:$A$1012,$W$2,'PIB-Mpal 2015-2022 Corrient '!$E$5:$E$1012,$A11) -> 139.46391 | V11: =SUMIFS('PIB-Mpal 2015-2022 Corrient '!Y$5:Y$1012,'PIB-Mpal 2015-2022 Corrient '!$A$5:$A$1012,$W$2,'PIB-Mpal 2015-2022 Corrient '!$E$5:$E$1012,$A11) -> 1519.4869 | W11: =V11/$V$5 -> 0.009895105 | X11: =INDEX(POBLACION!$C$4:$W$128,MATCH(A11,POBLACION!$A$4:$A$128,0),MATCH($W$2,POBLACION!$C$3:$W$3,0)) -> 80000 | Y11: =(T11/X11)*1000000 -> 17250.287 | Z11: =(V11/X11)*1000000 -> 18993.586 | AA11: =LOG(Y11) -> 4.2367963 | AB11: =LOG(Z11) -> 4.278607 | AE11: Terciarias ***
A12: 05266 | B12: Valle de Aburrá | C12: Área Metropolitana del Valle de Aburrá | D12: Envigado | E12: =SUMIFS('PIB-Mpal 2015-2022 Corrient '!H$5:H$1012,'PIB-Mpal 2015-2022 Corrient '!$A$5:$A$1012,$W$2,'PIB-Mpal 2015-2022 Corrient '!$E$5:$E$1012,$A12) -> 19.17739 | F12: =SUMIFS('PIB-Mpal 2015-2022 Corrient '!I$5:I$1012,'PIB-Mpal 2015-2022 Corrient '!$A$5:$A$1012,$W$2,'PIB-Mpal 2015-2022 Corrient '!$E$5:$E$1012,$A12) -> 0 | G12: =SUMIFS('PIB-Mpal 2015-2022 Corrient '!K$5:K$1012,'PIB-Mpal 2015-2022 Corrient '!$A$5:$A$1012,$W$2,'PIB-Mpal 2015-2022 Corrient '!$E$5:$E$1012,$A12) -> 2111.7556 | H12: =SUMIFS('PIB-Mpal 2015-2022 Corrient '!L$5:L$1012,'PIB-Mpal 2015-2022 Corrient '!$A$5:$A$1012,$W$2,'PIB-Mpal 2015-2022 Corrient '!$E$5:$E$1012,$A12) -> 586.36593 | I12: =SUMIFS('PIB-Mpal 2015-2022 Corrient '!N$5:N$1012,'PIB-Mpal 2015-2022 Corrient '!$A$5:$A$1012,$W$2,'PIB-Mpal 2015-2022 Corrient '!$E$5:$E$1012,$A12) -> 371.66604 | J12: =SUMIFS('PIB-Mpal 2015-2022 Corrient '!O$5:O$1012,'PIB-Mpal 2015-2022 Corrient '!$A$5:$A$1012,$W$2,'PIB-Mpal 2015-2022 Corrient '!$E$5:$E$1012,$A12) -> 1724.8722 | K12: =SUMIFS('PIB-Mpal 2015-2022 Corrient '!P$5:P$1012,'PIB-Mpal 2015-2022 Corrient '!$A$5:$A$1012,$W$2,'PIB-Mpal 2015-2022 Corrient '!$E$5:$E$1012,$A12) -> 323.23373 | L12: =SUMIFS('PIB-Mpal 2015-2022 Corrient '!Q$5:Q$1012,'PIB-Mpal 2015-2022 Corrient '!$A$5:$A$1012,$W$2,'PIB-Mpal 2015-2022 Corrient '!$E$5:$E$1012,$A12) -> 437.1145 | M12: =SUMIFS('PIB-Mpal 2015-2022 Corrient '!R$5:R$1012,'PIB-Mpal 2015-2022 Corrient '!$A$5:$A$1012,$W$2,'PIB-Mpal 2015-2022 Corrient '!$E$5:$E$1012,$A12) -> 1282.2303 | N12: =SUMIFS('PIB-Mpal 2015-2022 Corrient '!S$5:S$1012,'PIB-Mpal 2015-2022 Corrient '!$A$5:$A$1012,$W$2,'PIB-Mpal 2015-2022 Corrient '!$E$5:$E$1012,$A12) -> 1039.297 | O12: =SUMIFS('PIB-Mpal 2015-2022 Corrient '!T$5:T$1012,'PIB-Mpal 2015-2022 Corrient '!$A$5:$A$1012,$W$2,'PIB-Mpal 2015-2022 Corrient '!$E$5:$E$1012,$A12) -> 1034.9444 | P12: =SUMIFS('PIB-Mpal 2015-2022 Corrient '!U$5:U$1012,'PIB-Mpal 2015-2022 Corrient '!$A$5:$A$1012,$W$2,'PIB-Mpal 2015-2022 Corrient '!$E$5:$E$1012,$A12) -> 298.50785 | Q12: =SUMIFS('PIB-Mpal 2015-2022 Corrient '!J$5:J$1012,'PIB-Mpal 2015-2022 Corrient '!$A$5:$A$1012,$W$2,'PIB-Mpal 2015-2022 Corrient '!$E$5:$E$1012,$A12) -> 19.17739 | R12: =SUMIFS('PIB-Mpal 2015-2022 Corrient '!M$5:M$1012,'PIB-Mpal 2015-2022 Corrient '!$A$5:$A$1012,$W$2,'PIB-Mpal 2015-2022 Corrient '!$E$5:$E$1012,$A12) -> 2698.1216 | S12: =SUMIFS('PIB-Mpal 2015-2022 Corrient '!V$5:V$1012,'PIB-Mpal 2015-2022 Corrient '!$A$5:$A$1012,$W$2,'PIB-Mpal 2015-2022 Corrient '!$E$5:$E$1012,$A12) -> 6511.8661 | T12: =SUMIFS('PIB-Mpal 2015-2022 Corrient '!W$5:W$1012,'PIB-Mpal 2015-2022 Corrient '!$A$5:$A$1012,$W$2,'PIB-Mpal 2015-2022 Corrient '!$E$5:$E$1012,$A12) -> 9229.165 | U12: =SUMIFS('PIB-Mpal 2015-2022 Corrient '!X$5:X$1012,'PIB-Mpal 2015-2022 Corrient '!$A$5:$A$1012,$W$2,'PIB-Mpal 2015-2022 Corrient '!$E$5:$E$1012,$A12) -> 932.69129 | V12: =SUMIFS('PIB-Mpal 2015-2022 Corrient '!Y$5:Y$1012,'PIB-Mpal 2015-2022 Corrient '!$A$5:$A$1012,$W$2,'PIB-Mpal 2015-2022 Corrient '!$E$5:$E$1012,$A12) -> 10161.856 | W12: =V12/$V$5 -> 0.066175389 | X12: =INDEX(POBLACION!$C$4:$W$128,MATCH(A12,POBLACION!$A$4:$A$128,0),MATCH($W$2,POBLACION!$C$3:$W$3,0)) -> 236114 | Y12: =(T12/X12)*1000000 -> 39087.75 | Z12: =(V12/X12)*1000000 -> 43037.924 | AA12: =LOG(Y12) -> 4.5920407 | AB12: =LOG(Z12) -> 4.6338513 | AE12: Electricidad, gas y agua
A13: 05308 | B13: Valle de Aburrá | C13: Área Metropolitana del Valle de Aburrá | D13: Girardota | E13: =SUMIFS('PIB-Mpal 2015-2022 Corrient '!H$5:H$1012,'PIB-Mpal 2015-2022 Corrient '!$A$5:$A$1012,$W$2,'PIB-Mpal 2015-2022 Corrient '!$E$5:$E$1012,$A13) -> 57.517625 | F13: =SUMIFS('PIB-Mpal 2015-2022 Corrient '!I$5:I$1012,'PIB-Mpal 2015-2022 Corrient '!$A$5:$A$1012,$W$2,'PIB-Mpal 2015-2022 Corrient '!$E$5:$E$1012,$A13) -> 46.450931 | G13: =SUMIFS('PIB-Mpal 2015-2022 Corrient '!K$5:K$1012,'PIB-Mpal 2015-2022 Corrient '!$A$5:$A$1012,$W$2,'PIB-Mpal 2015-2022 Corrient '!$E$5:$E$1012,$A13) -> 1267.273 | H13: =SUMIFS('PIB-Mpal 2015-2022 Corrient '!L$5:L$1012,'PIB-Mpal 2015-2022 Corrient '!$A$5:$A$1012,$W$2,'PIB-Mpal 2015-2022 Corrient '!$E$5:$E$1012,$A13) -> 200.54087 | I13: =SUMIFS('PIB-Mpal 2015-2022 Corrient '!N$5:N$1012,'PIB-Mpal 2015-2022 Corrient '!$A$5:$A$1012,$W$2,'PIB-Mpal 2015-2022 Corrient '!$E$5:$E$1012,$A13) -> 63.030288 | J13: =SUMIFS('PIB-Mpal 2015-2022 Corrient '!O$5:O$1012,'PIB-Mpal 2015-2022 Corrient '!$A$5:$A$1012,$W$2,'PIB-Mpal 2015-2022 Corrient '!$E$5:$E$1012,$A13) -> 220.18386 | K13: =SUMIFS('PIB-Mpal 2015-2022 Corrient '!P$5:P$1012,'PIB-Mpal 2015-2022 Corrient '!$A$5:$A$1012,$W$2,'PIB-Mpal 2015-2022 Corrient '!$E$5:$E$1012,$A13) -> 29.585701 | L13: =SUMIFS('PIB-Mpal 2015-2022 Corrient '!Q$5:Q$1012,'PIB-Mpal 2015-2022 Corrient '!$A$5:$A$1012,$W$2,'PIB-Mpal 2015-2022 Corrient '!$E$5:$E$1012,$A13) -> 19.4922 | M13: =SUMIFS('PIB-Mpal 2015-2022 Corrient '!R$5:R$1012,'PIB-Mpal 2015-2022 Corrient '!$A$5:$A$1012,$W$2,'PIB-Mpal 2015-2022 Corrient '!$E$5:$E$1012,$A13) -> 88.402781 | N13: =SUMIFS('PIB-Mpal 2015-2022 Corrient '!S$5:S$1012,'PIB-Mpal 2015-2022 Corrient '!$A$5:$A$1012,$W$2,'PIB-Mpal 2015-2022 Corrient '!$E$5:$E$1012,$A13) -> 165.66759 | O13: =SUMIFS('PIB-Mpal 2015-2022 Corrient '!T$5:T$1012,'PIB-Mpal 2015-2022 Corrient '!$A$5:$A$1012,$W$2,'PIB-Mpal 2015-2022 Corrient '!$E$5:$E$1012,$A13) -> 101.09506 | P13: =SUMIFS('PIB-Mpal 2015-2022 Corrient '!U$5:U$1012,'PIB-Mpal 2015-2022 Corrient '!$A$5:$A$1012,$W$2,'PIB-Mpal 2015-2022 Corrient '!$E$5:$E$1012,$A13) -> 25.538343 | Q13: =SUMIFS('PIB-Mpal 2015-2022 Corrient '!J$5:J$1012,'PIB-Mpal 2015-2022 Corrient '!$A$5:$A$1012,$W$2,'PIB-Mpal 2015-2022 Corrient '!$E$5:$E$1012,$A13) -> 103.96856 | R13: =SUMIFS('PIB-Mpal 2015-2022 Corrient '!M$5:M$1012,'PIB-Mpal 2015-2022 Corrient '!$A$5:$A$1012,$W$2,'PIB-Mpal 2015-2022 Corrient '!$E$5:$E$1012,$A13) -> 1467.8139 | S13: =SUMIFS('PIB-Mpal 2015-2022 Corrient '!V$5:V$1012,'PIB-Mpal 2015-2022 Corrient '!$A$5:$A$1012,$W$2,'PIB-Mpal 2015-2022 Corrient '!$E$5:$E$1012,$A13) -> 712.99582 | T13: =SUMIFS('PIB-Mpal 2015-2022 Corrient '!W$5:W$1012,'PIB-Mpal 2015-2022 Corrient '!$A$5:$A$1012,$W$2,'PIB-Mpal 2015-2022 Corrient '!$E$5:$E$1012,$A13) -> 2284.7782 | U13: =SUMIFS('PIB-Mpal 2015-2022 Corrient '!X$5:X$1012,'PIB-Mpal 2015-2022 Corrient '!$A$5:$A$1012,$W$2,'PIB-Mpal 2015-2022 Corrient '!$E$5:$E$1012,$A13) -> 230.89768 | V13: =SUMIFS('PIB-Mpal 2015-2022 Corrient '!Y$5:Y$1012,'PIB-Mpal 2015-2022 Corrient '!$A$5:$A$1012,$W$2,'PIB-Mpal 2015-2022 Corrient '!$E$5:$E$1012,$A13) -> 2515.6759 | W13: =V13/$V$5 -> 0.016382423 | X13: =INDEX(POBLACION!$C$4:$W$128,MATCH(A13,POBLACION!$A$4:$A$128,0),MATCH($W$2,POBLACION!$C$3:$W$3,0)) -> 53162 | Y13: =(T13/X13)*1000000 -> 42977.658 | Z13: =(V13/X13)*1000000 -> 47320.942 | AA13: =LOG(Y13) -> 4.6332427 | AB13: =LOG(Z13) -> 4.6750534 | AE13: Comercio; reparación de vehículos automotores; Transporte; Alojamiento y servicios de comida
A14: 05360 | B14: Valle de Aburrá | C14: Área Metropolitana del Valle de Aburrá | D14: Itagüí | E14: =SUMIFS('PIB-Mpal 2015-2022 Corrient '!H$5:H$1012,'PIB-Mpal 2015-2022 Corrient '!$A$5:$A$1012,$W$2,'PIB-Mpal 2015-2022 Corrient '!$E$5:$E$1012,$A14) -> 0.28967671 | F14: =SUMIFS('PIB-Mpal 2015-2022 Corrient '!I$5:I$1012,'PIB-Mpal 2015-2022 Corrient '!$A$5:$A$1012,$W$2,'PIB-Mpal 2015-2022 Corrient '!$E$5:$E$1012,$A14) -> 0.28726646 | G14: =SUMIFS('PIB-Mpal 2015-2022 Corrient '!K$5:K$1012,'PIB-Mpal 2015-2022 Corrient '!$A$5:$A$1012,$W$2,'PIB-Mpal 2015-2022 Corrient '!$E$5:$E$1012,$A14) -> 2535.0013 | H14: =SUMIFS('PIB-Mpal 2015-2022 Corrient '!L$5:L$1012,'PIB-Mpal 2015-2022 Corrient '!$A$5:$A$1012,$W$2,'PIB-Mpal 2015-2022 Corrient '!$E$5:$E$1012,$A14) -> 630.62727 | I14: =SUMIFS('PIB-Mpal 2015-2022 Corrient '!N$5:N$1012,'PIB-Mpal 2015-2022 Corrient '!$A$5:$A$1012,$W$2,'PIB-Mpal 2015-2022 Corrient '!$E$5:$E$1012,$A14) -> 359.46392 | J14: =SUMIFS('PIB-Mpal 2015-2022 Corrient '!O$5:O$1012,'PIB-Mpal 2015-2022 Corrient '!$A$5:$A$1012,$W$2,'PIB-Mpal 2015-2022 Corrient '!$E$5:$E$1012,$A14) -> 1685.9972 | K14: =SUMIFS('PIB-Mpal 2015-2022 Corrient '!P$5:P$1012,'PIB-Mpal 2015-2022 Corrient '!$A$5:$A$1012,$W$2,'PIB-Mpal 2015-2022 Corrient '!$E$5:$E$1012,$A14) -> 270.1883 | L14: =SUMIFS('PIB-Mpal 2015-2022 Corrient '!Q$5:Q$1012,'PIB-Mpal 2015-2022 Corrient '!$A$5:$A$1012,$W$2,'PIB-Mpal 2015-2022 Corrient '!$E$5:$E$1012,$A14) -> 268.32346 | M14: =SUMIFS('PIB-Mpal 2015-2022 Corrient '!R$5:R$1012,'PIB-Mpal 2015-2022 Corrient '!$A$5:$A$1012,$W$2,'PIB-Mpal 2015-2022 Corrient '!$E$5:$E$1012,$A14) -> 750.04985 | N14: =SUMIFS('PIB-Mpal 2015-2022 Corrient '!S$5:S$1012,'PIB-Mpal 2015-2022 Corrient '!$A$5:$A$1012,$W$2,'PIB-Mpal 2015-2022 Corrient '!$E$5:$E$1012,$A14) -> 807.18369 | O14: =SUMIFS('PIB-Mpal 2015-2022 Corrient '!T$5:T$1012,'PIB-Mpal 2015-2022 Corrient '!$A$5:$A$1012,$W$2,'PIB-Mpal 2015-2022 Corrient '!$E$5:$E$1012,$A14) -> 690.12367 | P14: =SUMIFS('PIB-Mpal 2015-2022 Corrient '!U$5:U$1012,'PIB-Mpal 2015-2022 Corrient '!$A$5:$A$1012,$W$2,'PIB-Mpal 2015-2022 Corrient '!$E$5:$E$1012,$A14) -> 230.38862 | Q14: =SUMIFS('PIB-Mpal 2015-2022 Corrient '!J$5:J$1012,'PIB-Mpal 2015-2022 Corrient '!$A$5:$A$1012,$W$2,'PIB-Mpal 2015-2022 Corrient '!$E$5:$E$1012,$A14) -> 0.57694316 | R14: =SUMIFS('PIB-Mpal 2015-2022 Corrient '!M$5:M$1012,'PIB-Mpal 2015-2022 Corrient '!$A$5:$A$1012,$W$2,'PIB-Mpal 2015-2022 Corrient '!$E$5:$E$1012,$A14) -> 3165.6286 | S14: =SUMIFS('PIB-Mpal 2015-2022 Corrient '!V$5:V$1012,'PIB-Mpal 2015-2022 Corrient '!$A$5:$A$1012,$W$2,'PIB-Mpal 2015-2022 Corrient '!$E$5:$E$1012,$A14) -> 5061.7187 | T14: =SUMIFS('PIB-Mpal 2015-2022 Corrient '!W$5:W$1012,'PIB-Mpal 2015-2022 Corrient '!$A$5:$A$1012,$W$2,'PIB-Mpal 2015-2022 Corrient '!$E$5:$E$1012,$A14) -> 8227.9242 | U14: =SUMIFS('PIB-Mpal 2015-2022 Corrient '!X$5:X$1012,'PIB-Mpal 2015-2022 Corrient '!$A$5:$A$1012,$W$2,'PIB-Mpal 2015-2022 Corrient '!$E$5:$E$1012,$A14) -> 831.50677 | V14: =SUMIFS('PIB-Mpal 2015-2022 Corrient '!Y$5:Y$1012,'PIB-Mpal 2015-2022 Corrient '!$A$5:$A$1012,$W$2,'PIB-Mpal 2015-2022 Corrient '!$E$5:$E$1012,$A14) -> 9059.431 | W14: =V14/$V$5 -> 0.058996246 | X14: =INDEX(POBLACION!$C$4:$W$128,MATCH(A14,POBLACION!$A$4:$A$128,0),MATCH($W$2,POBLACION!$C$3:$W$3,0)) -> 283794 | Y14: =(T14/X14)*1000000 -> 28992.594 | Z14: =(V14/X14)*1000000 -> 31922.56 | AA14: =LOG(Y14) -> 4.4622871 | AB14: =LOG(Z14) -> 4.5040977 | AE14: Información y comunicaciones
A15: 05380 | B15: Valle de Aburrá | C15: Área Metropolitana del Valle de Aburrá | D15: La Estrella | E15: =SUMIFS('PIB-Mpal 2015-2022 Corrient '!H$5:H$1012,'PIB-Mpal 2015-2022 Corrient '!$A$5:$A$1012,$W$2,'PIB-Mpal 2015-2022 Corrient '!$E$5:$E$1012,$A15) -> 6.9451315 | F15: =SUMIFS('PIB-Mpal 2015-2022 Corrient '!I$5:I$1012,'PIB-Mpal 2015-2022 Corrient '!$A$5:$A$1012,$W$2,'PIB-Mpal 2015-2022 Corrient '!$E$5:$E$1012,$A15) -> 0 | G15: =SUMIFS('PIB-Mpal 2015-2022 Corrient '!K$5:K$1012,'PIB-Mpal 2015-2022 Corrient '!$A$5:$A$1012,$W$2,'PIB-Mpal 2015-2022 Corrient '!$E$5:$E$1012,$A15) -> 858.61339 | H15: =SUMIFS('PIB-Mpal 2015-2022 Corrient '!L$5:L$1012,'PIB-Mpal 2015-2022 Corrient '!$A$5:$A$1012,$W$2,'PIB-Mpal 2015-2022 Corrient '!$E$5:$E$1012,$A15) -> 177.21964 | I15: =SUMIFS('PIB-Mpal 2015-2022 Corrient '!N$5:N$1012,'PIB-Mpal 2015-2022 Corrient '!$A$5:$A$1012,$W$2,'PIB-Mpal 2015-2022 Corrient '!$E$5:$E$1012,$A15) -> 84.743604 | J15: =SUMIFS('PIB-Mpal 2015-2022 Corrient '!O$5:O$1012,'PIB-Mpal 2015-2022 Corrient '!$A$5:$A$1012,$W$2,'PIB-Mpal 2015-2022 Corrient '!$E$5:$E$1012,$A15) -> 259.59899 | K15: =SUMIFS('PIB-Mpal 2015-2022 Corrient '!P$5:P$1012,'PIB-Mpal 2015-2022 Corrient '!$A$5:$A$1012,$W$2,'PIB-Mpal 2015-2022 Corrient '!$E$5:$E$1012,$A15) -> 60.972989 | L15: =SUMIFS('PIB-Mpal 2015-2022 Corrient '!Q$5:Q$1012,'PIB-Mpal 2015-2022 Corrient '!$A$5:$A$1012,$W$2,'PIB-Mpal 2015-2022 Corrient '!$E$5:$E$1012,$A15) -> 30.423979 | M15: =SUMIFS('PIB-Mpal 2015-2022 Corrient '!R$5:R$1012,'PIB-Mpal 2015-2022 Corrient '!$A$5:$A$1012,$W$2,'PIB-Mpal 2015-2022 Corrient '!$E$5:$E$1012,$A15) -> 163.92914 | N15: =SUMIFS('PIB-Mpal 2015-2022 Corrient '!S$5:S$1012,'PIB-Mpal 2015-2022 Corrient '!$A$5:$A$1012,$W$2,'PIB-Mpal 2015-2022 Corrient '!$E$5:$E$1012,$A15) -> 170.91701 | O15: =SUMIFS('PIB-Mpal 2015-2022 Corrient '!T$5:T$1012,'PIB-Mpal 2015-2022 Corrient '!$A$5:$A$1012,$W$2,'PIB-Mpal 2015-2022 Corrient '!$E$5:$E$1012,$A15) -> 115.40729 | P15: =SUMIFS('PIB-Mpal 2015-2022 Corrient '!U$5:U$1012,'PIB-Mpal 2015-2022 Corrient '!$A$5:$A$1012,$W$2,'PIB-Mpal 2015-2022 Corrient '!$E$5:$E$1012,$A15) -> 39.896097 | Q15: =SUMIFS('PIB-Mpal 2015-2022 Corrient '!J$5:J$1012,'PIB-Mpal 2015-2022 Corrient '!$A$5:$A$1012,$W$2,'PIB-Mpal 2015-2022 Corrient '!$E$5:$E$1012,$A15) -> 6.9451315 | R15: =SUMIFS('PIB-Mpal 2015-2022 Corrient '!M$5:M$1012,'PIB-Mpal 2015-2022 Corrient '!$A$5:$A$1012,$W$2,'PIB-Mpal 2015-2022 Corrient '!$E$5:$E$1012,$A15) -> 1035.833 | S15: =SUMIFS('PIB-Mpal 2015-2022 Corrient '!V$5:V$1012,'PIB-Mpal 2015-2022 Corrient '!$A$5:$A$1012,$W$2,'PIB-Mpal 2015-2022 Corrient '!$E$5:$E$1012,$A15) -> 925.8891 | T15: =SUMIFS('PIB-Mpal 2015-2022 Corrient '!W$5:W$1012,'PIB-Mpal 2015-2022 Corrient '!$A$5:$A$1012,$W$2,'PIB-Mpal 2015-2022 Corrient '!$E$5:$E$1012,$A15) -> 1968.6673 | U15: =SUMIFS('PIB-Mpal 2015-2022 Corrient '!X$5:X$1012,'PIB-Mpal 2015-2022 Corrient '!$A$5:$A$1012,$W$2,'PIB-Mpal 2015-2022 Corrient '!$E$5:$E$1012,$A15) -> 198.95178 | V15: =SUMIFS('PIB-Mpal 2015-2022 Corrient '!Y$5:Y$1012,'PIB-Mpal 2015-2022 Corrient '!$A$5:$A$1012,$W$2,'PIB-Mpal 2015-2022 Corrient '!$E$5:$E$1012,$A15) -> 2167.6191 | W15: =V15/$V$5 -> 0.01411583 | X15: =INDEX(POBLACION!$C$4:$W$128,MATCH(A15,POBLACION!$A$4:$A$128,0),MATCH($W$2,POBLACION!$C$3:$W$3,0)) -> 73696 | Y15: =(T15/X15)*1000000 -> 26713.353 | Z15: =(V15/X15)*1000000 -> 29412.981 | AA15: =LOG(Y15) -> 4.4267284 | AB15: =LOG(Z15) -> 4.468539 | AE15: Actividades financieras y de seguros
A16: 05631 | B16: Valle de Aburrá | C16: Área Metropolitana del Valle de Aburrá | D16: Sabaneta | E16: =SUMIFS('PIB-Mpal 2015-2022 Corrient '!H$5:H$1012,'PIB-Mpal 2015-2022 Corrient '!$A$5:$A$1012,$W$2,'PIB-Mpal 2015-2022 Corrient '!$E$5:$E$1012,$A16) -> 8.5832277 | F16: =SUMIFS('PIB-Mpal 2015-2022 Corrient '!I$5:I$1012,'PIB-Mpal 2015-2022 Corrient '!$A$5:$A$1012,$W$2,'PIB-Mpal 2015-2022 Corrient '!$E$5:$E$1012,$A16) -> 0 | G16: =SUMIFS('PIB-Mpal 2015-2022 Corrient '!K$5:K$1012,'PIB-Mpal 2015-2022 Corrient '!$A$5:$A$1012,$W$2,'PIB-Mpal 2015-2022 Corrient '!$E$5:$E$1012,$A16) -> 1089.3549 | H16: =SUMIFS('PIB-Mpal 2015-2022 Corrient '!L$5:L$1012,'PIB-Mpal 2015-2022 Corrient '!$A$5:$A$1012,$W$2,'PIB-Mpal 2015-2022 Corrient '!$E$5:$E$1012,$A16) -> 224.10418 | I16: =SUMIFS('PIB-Mpal 2015-2022 Corrient '!N$5:N$1012,'PIB-Mpal 2015-2022 Corrient '!$A$5:$A$1012,$W$2,'PIB-Mpal 2015-2022 Corrient '!$E$5:$E$1012,$A16) -> 123.90379 | J16: =SUMIFS('PIB-Mpal 2015-2022 Corrient '!O$5:O$1012,'PIB-Mpal 2015-2022 Corrient '!$A$5:$A$1012,$W$2,'PIB-Mpal 2015-2022 Corrient '!$E$5:$E$1012,$A16) -> 641.20847 | K16: =SUMIFS('PIB-Mpal 2015-2022 Corrient '!P$5:P$1012,'PIB-Mpal 2015-2022 Corrient '!$A$5:$A$1012,$W$2,'PIB-Mpal 2015-2022 Corrient '!$E$5:$E$1012,$A16) -> 94.758127 | L16: =SUMIFS('PIB-Mpal 2015-2022 Corrient '!Q$5:Q$1012,'PIB-Mpal 2015-2022 Corrient '!$A$5:$A$1012,$W$2,'PIB-Mpal 2015-2022 Corrient '!$E$5:$E$1012,$A16) -> 73.817148 | M16: =SUMIFS('PIB-Mpal 2015-2022 Corrient '!R$5:R$1012,'PIB-Mpal 2015-2022 Corrient '!$A$5:$A$1012,$W$2,'PIB-Mpal 2015-2022 Corrient '!$E$5:$E$1012,$A16) -> 355.3355 | N16: =SUMIFS('PIB-Mpal 2015-2022 Corrient '!S$5:S$1012,'PIB-Mpal 2015-2022 Corrient '!$A$5:$A$1012,$W$2,'PIB-Mpal 2015-2022 Corrient '!$E$5:$E$1012,$A16) -> 330.03446 | O16: =SUMIFS('PIB-Mpal 2015-2022 Corrient '!T$5:T$1012,'PIB-Mpal 2015-2022 Corrient '!$A$5:$A$1012,$W$2,'PIB-Mpal 2015-2022 Corrient '!$E$5:$E$1012,$A16) -> 386.82788 | P16: =SUMIFS('PIB-Mpal 2015-2022 Corrient '!U$5:U$1012,'PIB-Mpal 2015-2022 Corrient '!$A$5:$A$1012,$W$2,'PIB-Mpal 2015-2022 Corrient '!$E$5:$E$1012,$A16) -> 70.729802 | Q16: =SUMIFS('PIB-Mpal 2015-2022 Corrient '!J$5:J$1012,'PIB-Mpal 2015-2022 Corrient '!$A$5:$A$1012,$W$2,'PIB-Mpal 2015-2022 Corrient '!$E$5:$E$1012,$A16) -> 8.5832277 | R16: =SUMIFS('PIB-Mpal 2015-2022 Corrient '!M$5:M$1012,'PIB-Mpal 2015-2022 Corrient '!$A$5:$A$1012,$W$2,'PIB-Mpal 2015-2022 Corrient '!$E$5:$E$1012,$A16) -> 1313.459 | S16: =SUMIFS('PIB-Mpal 2015-2022 Corrient '!V$5:V$1012,'PIB-Mpal 2015-2022 Corrient '!$A$5:$A$1012,$W$2,'PIB-Mpal 2015-2022 Corrient '!$E$5:$E$1012,$A16) -> 2076.6152 | T16: =SUMIFS('PIB-Mpal 2015-2022 Corrient '!W$5:W$1012,'PIB-Mpal 2015-2022 Corrient '!$A$5:$A$1012,$W$2,'PIB-Mpal 2015-2022 Corrient '!$E$5:$E$1012,$A16) -> 3398.6574 | U16: =SUMIFS('PIB-Mpal 2015-2022 Corrient '!X$5:X$1012,'PIB-Mpal 2015-2022 Corrient '!$A$5:$A$1012,$W$2,'PIB-Mpal 2015-2022 Corrient '!$E$5:$E$1012,$A16) -> 343.46533 | V16: =SUMIFS('PIB-Mpal 2015-2022 Corrient '!Y$5:Y$1012,'PIB-Mpal 2015-2022 Corrient '!$A$5:$A$1012,$W$2,'PIB-Mpal 2015-2022 Corrient '!$E$5:$E$1012,$A16) -> 3742.1228 | W16: =V16/$V$5 -> 0.024369212 | X16: =INDEX(POBLACION!$C$4:$W$128,MATCH(A16,POBLACION!$A$4:$A$128,0),MATCH($W$2,POBLACION!$C$3:$W$3,0)) -> 85484 | Y16: =(T16/X16)*1000000 -> 39757.82 | Z16: =(V16/X16)*1000000 -> 43775.71 | AA16: =LOG(Y16) -> 4.5994226 | AB16: =LOG(Z16) -> 4.6412332 | AE16: Actividades inmobiliarias
A17: SR02 | B17: Total Bajo Cauca | E17: =SUM(E18:E23) -> 220.37683 | F17: =SUM(F18:F23) -> 960.10778 | G17: =SUM(G18:G23) -> 48.362138 | H17: =SUM(H18:H23) -> 172.56225 | I17: =SUM(I18:I23) -> 182.51372 | J17: =SUM(J18:J23) -> 672.92201 | K17: =SUM(K18:K23) -> 97.300627 | L17: =SUM(L18:L23) -> 69.493036 | ... V17: =SUM(V18:V23) -> 3971.3794 | W17: =V17/$V$5 -> 0.025862162 | X17: =SUM(X18:X23) -> 255064 | Y17: =(T17/X17)*1000000 -> 14141.047 | Z17: =(V17/X17)*1000000 -> 15570.129 | AA17: =LOG(Y17) -> 4.1504816 | AB17: =LOG(Z17) -> 4.1922922 | AE17: Actividades profesionales, científicas y técnicas; Actividades de servicios administrativos y de apoyo
A18: 05120 | B18: Bajo Cauca | C18: Región de Planeación y Gestión del Bajo Cauca - RPG | D18: Cáceres | E18: =SUMIFS('PIB-Mpal 2015-2022 Corrient '!H$5:H$1012,'PIB-Mpal 2015-2022 Corrient '!$A$5:$A$1012,$W$2,'PIB-Mpal 2015-2022 Corrient '!$E$5:$E$1012,$A18) -> 46.549862 | F18: =SUMIFS('PIB-Mpal 2015-2022 Corrient '!I$5:I$1012,'PIB-Mpal 2015-2022 Corrient '!$A$5:$A$1012,$W$2,'PIB-Mpal 2015-2022 Corrient '!$E$5:$E$1012,$A18) -> 56.143363 | G18: =SUMIFS('PIB-Mpal 2015-2022 Corrient '!K$5:K$1012,'PIB-Mpal 2015-2022 Corrient '!$A$5:$A$1012,$W$2,'PIB-Mpal 2015-2022 Corrient '!$E$5:$E$1012,$A18) -> 2.7428706 | H18: =SUMIFS('PIB-Mpal 2015-2022 Corrient '!L$5:L$1012,'PIB-Mpal 2015-2022 Corrient '!$A$5:$A$1012,$W$2,'PIB-Mpal 2015-2022 Corrient '!$E$5:$E$1012,$A18) -> 26.28187 | I18: =SUMIFS('PIB-Mpal 2015-2022 Corrient '!N$5:N$1012,'PIB-Mpal 2015-2022 Corrient '!$A$5:$A$1012,$W$2,'PIB-Mpal 2015-2022 Corrient '!$E$5:$E$1012,$A18) -> 26.841665 | J18: =SUMIFS('PIB-Mpal 2015-2022 Corrient '!O$5:O$1012,'PIB-Mpal 2015-2022 Corrient '!$A$5:$A$1012,$W$2,'PIB-Mpal 2015-2022 Corrient '!$E$5:$E$1012,$A18) -> 87.963078 | K18: =SUMIFS('PIB-Mpal 2015-2022 Corrient '!P$5:P$1012,'PIB-Mpal 2015-2022 Corrient '!$A$5:$A$1012,$W$2,'PIB-Mpal 2015-2022 Corrient '!$E$5:$E$1012,$A18) -> 13.090874 | L18: =SUMIFS('PIB-Mpal 2015-2022 Corrient '!Q$5:Q$1012,'PIB-Mpal 2015-2022 Corrient '!$A$5:$A$1012,$W$2,'PIB-Mpal 2015-2022 Corrient '!$E$5:$E$1012,$A18) -> 5.0951843 | M18: =SUMIFS('PIB-Mpal 2015-2022 Corrient '!R$5:R$1012,'PIB-Mpal 2015-2022 Corrient '!$A$5:$A$1012,$W$2,'PIB-Mpal 2015-2022 Corrient '!$E$5:$E$1012,$A18) -> 16.245561 | N18: =SUMIFS('PIB-Mpal 2015-2022 Corrient '!S$5:S$1012,'PIB-Mpal 2015-2022 Corrient '!$A$5:$A$1012,$W$2,'PIB-Mpal 2015-2022 Corrient '!$E$5:$E$1012,$A18) -> 45.031682 | O18: =SUMIFS('PIB-Mpal 2015-2022 Corrient '!T$5:T$1012,'PIB-Mpal 2015-2022 Corrient '!$A$5:$A$1012,$W$2,'PIB-Mpal 2015-2022 Corrient '!$E$5:$E$1012,$A18) -> 77.680412 | P18: =SUMIFS('PIB-Mpal 2015-2022 Corrient '!U$5:U$1012,'PIB-Mpal 2015-2022 Corrient '!$A$5:$A$1012,$W$2,'PIB-Mpal 2015-2022 Corrient '!$E$5:$E$1012,$A18) -> 9.3334675 | Q18: =SUMIFS('PIB-Mpal 2015-2022 Corrient '!J$5:J$1012,'PIB-Mpal 2015-2022 Corrient '!$A$5:$A$1012,$W$2,'PIB-Mpal 2015-2022 Corrient '!$E$5:$E$1012,$A18) -> 102.69322 | R18: =SUMIFS('PIB-Mpal 2015-2022 Corrient '!M$5:M$1012,'PIB-Mpal 2015-2022 Corrient '!$A$5:$A$1012,$W$2,'PIB-Mpal 2015-2022 Corrient '!$E$5:$E$1012,$A18) -> 29.024741 | S18: =SUMIFS('PIB-Mpal 2015-2022 Corrient '!V$5:V$1012,'PIB-Mpal 2015-2022 Corrient '!$A$5:$A$1012,$W$2,'PIB-Mpal 2015-2022 Corrient '!$E$5:$E$1012,$A18) -> 281.28192 | T18: =SUMIFS('PIB-Mpal 2015-2022 Corrient '!W$5:W$1012,'PIB-Mpal 2015-2022 Corrient '!$A$5:$A$1012,$W$2,'PIB-Mpal 2015-2022 Corrient '!$E$5:$E$1012,$A18) -> 412.99989 | U18: =SUMIFS('PIB-Mpal 2015-2022 Corrient '!X$5:X$1012,'PIB-Mpal 2015-2022 Corrient '!$A$5:$A$1012,$W$2,'PIB-Mpal 2015-2022 Corrient '!$E$5:$E$1012,$A18) -> 41.737405 | V18: =SUMIFS('PIB-Mpal 2015-2022 Corrient '!Y$5:Y$1012,'PIB-Mpal 2015-2022 Corrient '!$A$5:$A$1012,$W$2,'PIB-Mpal 2015-2022 Corrient '!$E$5:$E$1012,$A18) -> 454.73729 | W18: =V18/$V$5 -> 0.0029613111 | X18: =INDEX(POBLACION!$C$4:$W$128,MATCH(A18,POBLACION!$A$4:$A$128,0),MATCH($W$2,POBLACION!$C$3:$W$3,0)) -> 29716 | Y18: =(T18/X18)*1000000 -> 13898.233 | Z18: =(V18/X18)*1000000 -> 15302.776 | AA18: =LOG(Y18) -> 4.1429596 | AB18: =LOG(Z18) -> 4.1847702 | AE18: Administración pública ; Educación; Salud
A19: 05154 | B19: Bajo Cauca | C19: Región de Planeación y Gestión del Bajo Cauca - RPG | D19: Caucasia | E19: =SUMIFS('PIB-Mpal 2015-2022 Corrient '!H$5:H$1012,'PIB-Mpal 2015-2022 Corrient '!$A$5:$A$1012,$W$2,'PIB-Mpal 2015-2022 Corrient '!$E$5:$E$1012,$A19) -> 37.118345 | F19: =SUMIFS('PIB-Mpal 2015-2022 Corrient '!I$5:I$1012,'PIB-Mpal 2015-2022 Corrient '!$A$5:$A$1012,$W$2,'PIB-Mpal 2015-2022 Corrient '!$E$5:$E$1012,$A19) -> 340.74258 | G19: =SUMIFS('PIB-Mpal 2015-2022 Corrient '!K$5:K$1012,'PIB-Mpal 2015-2022 Corrient '!$A$5:$A$1012,$W$2,'PIB-Mpal 2015-2022 Corrient '!$E$5:$E$1012,$A19) -> 20.509929 | H19: =SUMIFS('PIB-Mpal 2015-2022 Corrient '!L$5:L$1012,'PIB-Mpal 2015-2022 Corrient '!$A$5:$A$1012,$W$2,'PIB-Mpal 2015-2022 Corrient '!$E$5:$E$1012,$A19) -> 65.554047 | I19: =SUMIFS('PIB-Mpal 2015-2022 Corrient '!N$5:N$1012,'PIB-Mpal 2015-2022 Corrient '!$A$5:$A$1012,$W$2,'PIB-Mpal 2015-2022 Corrient '!$E$5:$E$1012,$A19) -> 60.715109 | J19: =SUMIFS('PIB-Mpal 2015-2022 Corrient '!O$5:O$1012,'PIB-Mpal 2015-2022 Corrient '!$A$5:$A$1012,$W$2,'PIB-Mpal 2015-2022 Corrient '!$E$5:$E$1012,$A19) -> 297.94491 | K19: =SUMIFS('PIB-Mpal 2015-2022 Corrient '!P$5:P$1012,'PIB-Mpal 2015-2022 Corrient '!$A$5:$A$1012,$W$2,'PIB-Mpal 2015-2022 Corrient '!$E$5:$E$1012,$A19) -> 36.662801 | L19: =SUMIFS('PIB-Mpal 2015-2022 Corrient '!Q$5:Q$1012,'PIB-Mpal 2015-2022 Corrient '!$A$5:$A$1012,$W$2,'PIB-Mpal 2015-2022 Corrient '!$E$5:$E$1012,$A19) -> 34.059352 | M19: =SUMIFS('PIB-Mpal 2015-2022 Corrient '!R$5:R$1012,'PIB-Mpal 2015-2022 Corrient '!$A$5:$A$1012,$W$2,'PIB-Mpal 2015-2022 Corrient '!$E$5:$E$1012,$A19) -> 70.717159 | N19: =SUMIFS('PIB-Mpal 2015-2022 Corrient '!S$5:S$1012,'PIB-Mpal 2015-2022 Corrient '!$A$5:$A$1012,$W$2,'PIB-Mpal 2015-2022 Corrient '!$E$5:$E$1012,$A19) -> 139.30738 | O19: =SUMIFS('PIB-Mpal 2015-2022 Corrient '!T$5:T$1012,'PIB-Mpal 2015-2022 Corrient '!$A$5:$A$1012,$W$2,'PIB-Mpal 2015-2022 Corrient '!$E$5:$E$1012,$A19) -> 224.61825 | P19: =SUMIFS('PIB-Mpal 2015-2022 Corrient '!U$5:U$1012,'PIB-Mpal 2015-2022 Corrient '!$A$5:$A$1012,$W$2,'PIB-Mpal 2015-2022 Corrient '!$E$5:$E$1012,$A19) -> 24.743604 | Q19: =SUMIFS('PIB-Mpal 2015-2022 Corrient '!J$5:J$1012,'PIB-Mpal 2015-2022 Corrient '!$A$5:$A$1012,$W$2,'PIB-Mpal 2015-2022 Corrient '!$E$5:$E$1012,$A19) -> 377.86092 | R19: =SUMIFS('PIB-Mpal 2015-2022 Corrient '!M$5:M$1012,'PIB-Mpal 2015-2022 Corrient '!$A$5:$A$1012,$W$2,'PIB-Mpal 2015-2022 Corrient '!$E$5:$E$1012,$A19) -> 86.063976 | S19: =SUMIFS('PIB-Mpal 2015-2022 Corrient '!V$5:V$1012,'PIB-Mpal 2015-2022 Corrient '!$A$5:$A$1012,$W$2,'PIB-Mpal 2015-2022 Corrient '!$E$5:$E$1012,$A19) -> 888.76857 | T19: =SUMIFS('PIB-Mpal 2015-2022 Corrient '!W$5:W$1012,'PIB-Mpal 2015-2022 Corrient '!$A$5:$A$1012,$W$2,'PIB-Mpal 2015-2022 Corrient '!$E$5:$E$1012,$A19) -> 1352.6935 | U19: =SUMIFS('PIB-Mpal 2015-2022 Corrient '!X$5:X$1012,'PIB-Mpal 2015-2022 Corrient '!$A$5:$A$1012,$W$2,'PIB-Mpal 2015-2022 Corrient '!$E$5:$E$1012,$A19) -> 136.70201 | V19: =SUMIFS('PIB-Mpal 2015-2022 Corrient '!Y$5:Y$1012,'PIB-Mpal 2015-2022 Corrient '!$A$5:$A$1012,$W$2,'PIB-Mpal 2015-2022 Corrient '!$E$5:$E$1012,$A19) -> 1489.3955 | W19: =V19/$V$5 -> 0.0096991458 | X19: =INDEX(POBLACION!$C$4:$W$128,MATCH(A19,POBLACION!$A$4:$A$128,0),MATCH($W$2,POBLACION!$C$3:$W$3,0)) -> 93044 | Y19: =(T19/X19)*1000000 -> 14538.213 | Z19: =(V19/X19)*1000000 -> 16007.432 | AA19: =LOG(Y19) -> 4.162511 | AB19: =LOG(Z19) -> 4.2043217 | AE19: Actividades artísticas, de entretenimiento y recreación; Actividades de los hogares individuales
A20: 05250 | B20: Bajo Cauca | C20: Región de Planeación y Gestión del Bajo Cauca - RPG | D20: El Bagre | E20: =SUMIFS('PIB-Mpal 2015-2022 Corrient '!H$5:H$1012,'PIB-Mpal 2015-2022 Corrient '!$A$5:$A$1012,$W$2,'PIB-Mpal 2015-2022 Corrient '!$E$5:$E$1012,$A20) -> 25.948993 | F20: =SUMIFS('PIB-Mpal 2015-2022 Corrient '!I$5:I$1012,'PIB-Mpal 2015-2022 Corrient '!$A$5:$A$1012,$W$2,'PIB-Mpal 2015-2022 Corrient '!$E$5:$E$1012,$A20) -> 307.03531 | G20: =SUMIFS('PIB-Mpal 2015-2022 Corrient '!K$5:K$1012,'PIB-Mpal 2015-2022 Corrient '!$A$5:$A$1012,$W$2,'PIB-Mpal 2015-2022 Corrient '!$E$5:$E$1012,$A20) -> 2.7200067 | H20: =SUMIFS('PIB-Mpal 2015-2022 Corrient '!L$5:L$1012,'PIB-Mpal 2015-2022 Corrient '!$A$5:$A$1012,$W$2,'PIB-Mpal 2015-2022 Corrient '!$E$5:$E$1012,$A20) -> 37.185969 | I20: =SUMIFS('PIB-Mpal 2015-2022 Corrient '!N$5:N$1012,'PIB-Mpal 2015-2022 Corrient '!$A$5:$A$1012,$W$2,'PIB-Mpal 2015-2022 Corrient '!$E$5:$E$1012,$A20) -> 28.554518 | J20: =SUMIFS('PIB-Mpal 2015-2022 Corrient '!O$5:O$1012,'PIB-Mpal 2015-2022 Corrient '!$A$5:$A$1012,$W$2,'PIB-Mpal 2015-2022 Corrient '!$E$5:$E$1012,$A20) -> 133.27434 | K20: =SUMIFS('PIB-Mpal 2015-2022 Corrient '!P$5:P$1012,'PIB-Mpal 2015-2022 Corrient '!$A$5:$A$1012,$W$2,'PIB-Mpal 2015-2022 Corrient '!$E$5:$E$1012,$A20) -> 20.854131 | L20: =SUMIFS('PIB-Mpal 2015-2022 Corrient '!Q$5:Q$1012,'PIB-Mpal 2015-2022 Corrient '!$A$5:$A$1012,$W$2,'PIB-Mpal 2015-2022 Corrient '!$E$5:$E$1012,$A20) -> 13.801788 | M20: =SUMIFS('PIB-Mpal 2015-2022 Corrient '!R$5:R$1012,'PIB-Mpal 2015-2022 Corrient '!$A$5:$A$1012,$W$2,'PIB-Mpal 2015-2022 Corrient '!$E$5:$E$1012,$A20) -> 28.191162 | N20: =SUMIFS('PIB-Mpal 2015-2022 Corrient '!S$5:S$1012,'PIB-Mpal 2015-2022 Corrient '!$A$5:$A$1012,$W$2,'PIB-Mpal 2015-2022 Corrient '!$E$5:$E$1012,$A20) -> 75.476661 | O20: =SUMIFS('PIB-Mpal 2015-2022 Corrient '!T$5:T$1012,'PIB-Mpal 2015-2022 Corrient '!$A$5:$A$1012,$W$2,'PIB-Mpal 2015-2022 Corrient '!$E$5:$E$1012,$A20) -> 98.0367 | P20: =SUMIFS('PIB-Mpal 2015-2022 Corrient '!U$5:U$1012,'PIB-Mpal 2015-2022 Corrient '!$A$5:$A$1012,$W$2,'PIB-Mpal 2015-2022 Corrient '!$E$5:$E$1012,$A20) -> 13.164174 | Q20: =SUMIFS('PIB-Mpal 2015-2022 Corrient '!J$5:J$1012,'PIB-Mpal 2015-2022 Corrient '!$A$5:$A$1012,$W$2,'PIB-Mpal 2015-2022 Corrient '!$E$5:$E$1012,$A20) -> 332.98431 | R20: =SUMIFS('PIB-Mpal 2015-2022 Corrient '!M$5:M$1012,'PIB-Mpal 2015-2022 Corrient '!$A$5:$A$1012,$W$2,'PIB-Mpal 2015-2022 Corrient '!$E$5:$E$1012,$A20) -> 39.905976 | S20: =SUMIFS('PIB-Mpal 2015-2022 Corrient '!V$5:V$1012,'PIB-Mpal 2015-2022 Corrient '!$A$5:$A$1012,$W$2,'PIB-Mpal 2015-2022 Corrient '!$E$5:$E$1012,$A20) -> 411.35347 | T20: =SUMIFS('PIB-Mpal 2015-2022 Corrient '!W$5:W$1012,'PIB-Mpal 2015-2022 Corrient '!$A$5:$A$1012,$W$2,'PIB-Mpal 2015-2022 Corrient '!$E$5:$E$1012,$A20) -> 784.24376 | U20: =SUMIFS('PIB-Mpal 2015-2022 Corrient '!X$5:X$1012,'PIB-Mpal 2015-2022 Corrient '!$A$5:$A$1012,$W$2,'PIB-Mpal 2015-2022 Corrient '!$E$5:$E$1012,$A20) -> 79.254983 | V20: =SUMIFS('PIB-Mpal 2015-2022 Corrient '!Y$5:Y$1012,'PIB-Mpal 2015-2022 Corrient '!$A$5:$A$1012,$W$2,'PIB-Mpal 2015-2022 Corrient '!$E$5:$E$1012,$A20) -> 863.49874 | W20: =V20/$V$5 -> 0.0056232211 | X20: =INDEX(POBLACION!$C$4:$W$128,MATCH(A20,POBLACION!$A$4:$A$128,0),MATCH($W$2,POBLACION!$C$3:$W$3,0)) -> 52925 | Y20: =(T20/X20)*1000000 -> 14818.021 | Z20: =(V20/X20)*1000000 -> 16315.517 | AA20: =LOG(Y20) -> 4.1707902 | AB20: =LOG(Z20) -> 4.2126008
A21: 05495 | B21: Bajo Cauca | C21: Región de Planeación y Gestión del Bajo Cauca - RPG | D21: Nechí | E21: =SUMIFS('PIB-Mpal 2015-2022 Corrient '!H$5:H$1012,'PIB-Mpal 2015-2022 Corrient '!$A$5:$A$1012,$W$2,'PIB-Mpal 2015-2022 Corrient '!$E$5:$E$1012,$A21) -> 45.075792 | F21: =SUMIFS('PIB-Mpal 2015-2022 Corrient '!I$5:I$1012,'PIB-Mpal 2015-2022 Corrient '!$A$5:$A$1012,$W$2,'PIB-Mpal 2015-2022 Corrient '!$E$5:$E$1012,$A21) -> 41.440664 | G21: =SUMIFS('PIB-Mpal 2015-2022 Corrient '!K$5:K$1012,'PIB-Mpal 2015-2022 Corrient '!$A$5:$A$1012,$W$2,'PIB-Mpal 2015-2022 Corrient '!$E$5:$E$1012,$A21) -> 10.269331 | H21: =SUMIFS('PIB-Mpal 2015-2022 Corrient '!L$5:L$1012,'PIB-Mpal 2015-2022 Corrient '!$A$5:$A$1012,$W$2,'PIB-Mpal 2015-2022 Corrient '!$E$5:$E$1012,$A21) -> 11.828223 | I21: =SUMIFS('PIB-Mpal 2015-2022 Corrient '!N$5:N$1012,'PIB-Mpal 2015-2022 Corrient '!$A$5:$A$1012,$W$2,'PIB-Mpal 2015-2022 Corrient '!$E$5:$E$1012,$A21) -> 20.723824 | J21: =SUMIFS('PIB-Mpal 2015-2022 Corrient '!O$5:O$1012,'PIB-Mpal 2015-2022 Corrient '!$A$5:$A$1012,$W$2,'PIB-Mpal 2015-2022 Corrient '!$E$5:$E$1012,$A21) -> 56.863829 | K21: =SUMIFS('PIB-Mpal 2015-2022 Corrient '!P$5:P$1012,'PIB-Mpal 2015-2022 Corrient '!$A$5:$A$1012,$W$2,'PIB-Mpal 2015-2022 Corrient '!$E$5:$E$1012,$A21) -> 8.4259202 | L21: =SUMIFS('PIB-Mpal 2015-2022 Corrient '!Q$5:Q$1012,'PIB-Mpal 2015-2022 Corrient '!$A$5:$A$1012,$W$2,'PIB-Mpal 2015-2022 Corrient '!$E$5:$E$1012,$A21) -> 5.2944819 | M21: =SUMIFS('PIB-Mpal 2015-2022 Corrient '!R$5:R$1012,'PIB-Mpal 2015-2022 Corrient '!$A$5:$A$1012,$W$2,'PIB-Mpal 2015-2022 Corrient '!$E$5:$E$1012,$A21) -> 14.517612 | N21: =SUMIFS('PIB-Mpal 2015-2022 Corrient '!S$5:S$1012,'PIB-Mpal 2015-2022 Corrient '!$A$5:$A$1012,$W$2,'PIB-Mpal 2015-2022 Corrient '!$E$5:$E$1012,$A21) -> 29.988519 | O21: =SUMIFS('PIB-Mpal 2015-2022 Corrient '!T$5:T$1012,'PIB-Mpal 2015-2022 Corrient '!$A$5:$A$1012,$W$2,'PIB-Mpal 2015-2022 Corrient '!$E$5:$E$1012,$A21) -> 54.044731 | P21: =SUMIFS('PIB-Mpal 2015-2022 Corrient '!U$5:U$1012,'PIB-Mpal 2015-2022 Corrient '!$A$5:$A$1012,$W$2,'PIB-Mpal 2015-2022 Corrient '!$E$5:$E$1012,$A21) -> 6.8018295 | Q21: =SUMIFS('PIB-Mpal 2015-2022 Corrient '!J$5:J$1012,'PIB-Mpal 2015-2022 Corrient '!$A$5:$A$1012,$W$2,'PIB-Mpal 2015-2022 Corrient '!$E$5:$E$1012,$A21) -> 86.516457 | R21: =SUMIFS('PIB-Mpal 2015-2022 Corrient '!M$5:M$1012,'PIB-Mpal 2015-2022 Corrient '!$A$5:$A$1012,$W$2,'PIB-Mpal 2015-2022 Corrient '!$E$5:$E$1012,$A21) -> 22.097555 | S21: =SUMIFS('PIB-Mpal 2015-2022 Corrient '!V$5:V$1012,'PIB-Mpal 2015-2022 Corrient '!$A$5:$A$1012,$W$2,'PIB-Mpal 2015-2022 Corrient '!$E$5:$E$1012,$A21) -> 196.66075 | T21: =SUMIFS('PIB-Mpal 2015-2022 Corrient '!W$5:W$1012,'PIB-Mpal 2015-2022 Corrient '!$A$5:$A$1012,$W$2,'PIB-Mpal 2015-2022 Corrient '!$E$5:$E$1012,$A21) -> 305.27476 | U21: =SUMIFS('PIB-Mpal 2015-2022 Corrient '!X$5:X$1012,'PIB-Mpal 2015-2022 Corrient '!$A$5:$A$1012,$W$2,'PIB-Mpal 2015-2022 Corrient '!$E$5:$E$1012,$A21) -> 30.850798 | V21: =SUMIFS('PIB-Mpal 2015-2022 Corrient '!Y$5:Y$1012,'PIB-Mpal 2015-2022 Corrient '!$A$5:$A$1012,$W$2,'PIB-Mpal 2015-2022 Corrient '!$E$5:$E$1012,$A21) -> 336.12556 | W21: =V21/$V$5 -> 0.0021888953 | X21: =INDEX(POBLACION!$C$4:$W$128,MATCH(A21,POBLACION!$A$4:$A$128,0),MATCH($W$2,POBLACION!$C$3:$W$3,0)) -> 26652 | Y21: =(T21/X21)*1000000 -> 11454.103 | Z21: =(V21/X21)*1000000 -> 12611.645 | AA21: =LOG(Y21) -> 4.0589611 | AB21: =LOG(Z21) -> 4.1007717
